<?xml version="1.0" ?>
<!-- =================================================================================== -->
<!-- |    This document was autogenerated by xacro from src/sim_mdrs/urdf/arm.urdf.xacro | -->
<!-- |    EDITING THIS FILE BY HAND IS NOT RECOMMENDED                                 | -->
<!-- =================================================================================== -->
<robot name="my_robot_arm">
  <material name="blue">
    <color rgba="0.0 0.0 1.0 1.0"/>
  </material>
  <material name="red">
    <color rgba="1.0 0.0 0.0 1.0"/>
  </material>
  <material name="gray">
    <color rgba="0.5 0.5 0.5 1.0"/>
  </material>
  <!-- Base Link -->
  <link name="base_link">
    <visual>
      <geometry>
        <cylinder length="0.5" radius="0.05"/>
      </geometry>
      <material name="blue"/>
    </visual>
  </link>
  <!-- Joint 1 -->
  <joint name="joint1" type="revolute">
    <parent link="base_link"/>
    <child link="first_link"/>
    <origin rpy="0 0 0" xyz="0 0 0.25"/>
    <axis xyz="0 0 1"/>
    <limit effort="10" lower="-1.57" upper="1.57" velocity="1"/>
  </joint>
  <!-- Arm Link -->
  <link name="first_link">
    <visual>
      <geometry>
        <cylinder length="0.5" radius="0.05"/>
      </geometry>
      <material name="red"/>
    </visual>
  </link>
  <joint name="joint2" type="revolute">
    <parent link="first_link"/>
    <child link="second_link"/>
    <origin rpy="0 0 0" xyz="0 0 0.25"/>
    <axis xyz="0 0 1"/>
    <limit effort="10" lower="-1.57" upper="1.57" velocity="1"/>
  </joint>
  <link name="second_link">
    <visual>
      <geometry>
        <cylinder length="0.5" radius="0.05"/>
      </geometry>
      <material name="red"/>
    </visual>
  </link>
  <joint name="joint3" type="revolute">
    <parent link="second_link"/>
    <child link="third_link"/>
    <origin rpy="0 0 0" xyz="0 0 0.25"/>
    <axis xyz="0 0 1"/>
    <limit effort="10" lower="-1.57" upper="1.57" velocity="1"/>
  </joint>
  <link name="third_link">
    <visual>
      <geometry>
        <cylinder length="0.5" radius="0.05"/>
      </geometry>
      <material name="red"/>
    </visual>
  </link>
  <joint name="joint4" type="revolute">
    <parent link="third_link"/>
    <child link="arm_link"/>
    <origin rpy="0 0 0" xyz="0 0 0.25"/>
    <axis xyz="0 0 1"/>
    <limit effort="10" lower="-1.57" upper="1.57" velocity="1"/>
  </joint>
  <link name="arm_link">
    <visual>
      <geometry>
        <cylinder length="1.0" radius="0.05"/>
      </geometry>
      <material name="red"/>
    </visual>
  </link>
  <!-- Gripper Base -->
  <link name="gripper_base">
    <visual>
      <geometry>
        <box size="0.1 0.1 0.02"/>
      </geometry>
      <material name="gray"/>
    </visual>
  </link>
  <joint name="gripper_joint" type="fixed">
    <parent link="arm_link"/>
    <child link="gripper_base"/>
    <origin rpy="0 0 0" xyz="0 0 0.5"/>
  </joint>
  <!-- Left Gripper Finger -->
  <link name="left_finger">
    <visual>
      <geometry>
        <box size="0.02 0.1 0.02"/>
      </geometry>
      <material name="blue"/>
    </visual>
  </link>
  <joint name="left_finger_joint" type="prismatic">
    <parent link="gripper_base"/>
    <child link="left_finger"/>
    <origin rpy="0 0 0" xyz="0.05 0 0.01"/>
    <axis xyz="0 1 0"/>
    <limit effort="10" lower="0" upper="0.04" velocity="0.05"/>
  </joint>
  <!-- Right Gripper Finger -->
  <link name="right_finger">
    <visual>
      <geometry>
        <box size="0.02 0.1 0.02"/>
      </geometry>
      <material name="blue"/>
    </visual>
  </link>
  <joint name="right_finger_joint" type="prismatic">
    <parent link="gripper_base"/>
    <child link="right_finger"/>
    <origin rpy="0 0 0" xyz="-0.05 0 0.01"/>
    <axis xyz="0 -1 0"/>
    <limit effort="10" lower="0" upper="0.04" velocity="0.05"/>
  </joint>
</robot>
